# 异步函数call_next的函数体中指定变量app_exc的数据类型为Exception，Exception是什么
在 Python 中，`Exception` 是所有内置异常类的基类。在 `call_next` 异步函数体中指定变量 `app_exc` 的数据类型为 `Exception`，意味着这个变量用于存储在请求处理过程中可能发生的任何异常对象。下面从几个方面详细介绍 `Exception` 以及在这个上下文中的作用：

### 1. `Exception` 类的基本概念
在 Python 的异常处理机制中，`Exception` 处于异常类层次结构的核心位置。几乎所有内置的异常类都直接或间接地继承自 `Exception` 类。例如，`ValueError`、`TypeError`、`FileNotFoundError` 等常见的异常类都是 `Exception` 的子类。以下是一个简单的示例，展示了不同异常类与 `Exception` 的继承关系：
```python
# 定义一个 ValueError 异常对象
try:
    raise ValueError("This is a value error.")
except Exception as e:
    print(f"Caught an exception of type {type(e).__name__}: {e}")
```
在这个示例中，`ValueError` 是 `Exception` 的子类，当捕获 `Exception` 类型的异常时，能够捕获到 `ValueError` 异常。

### 2. 在 `call_next` 函数中使用 `Exception` 类型变量的作用
在 `call_next` 函数中，`app_exc` 变量用于存储在调用 `self.app(scope, receive_or_disconnect, send_no_error)` 过程中可能抛出的异常。具体代码如下：
```python
async def call_next(request: Request) -> Response:
    app_exc: Exception | None = None
    try:
        await self.app(scope, receive_or_disconnect, send_no_error)
    except Exception as exc:
        app_exc = exc
    # 后续处理
    if app_exc is not None:
        raise app_exc
```
- **异常捕获**：使用 `try-except` 块捕获 `self.app` 调用过程中抛出的任何异常，并将其赋值给 `app_exc` 变量。这样可以避免异常直接中断 `call_next` 函数的执行，而是将异常信息保存下来，以便后续处理。
- **异常传播**：在后续的代码中，如果 `app_exc` 不为 `None`，则重新抛出该异常，将异常信息传递给调用者，确保异常能够被正确处理。

### 3. 总结
在 `call_next` 函数中，将 `app_exc` 变量的数据类型指定为 `Exception`，是为了能够捕获并处理在请求处理过程中可能发生的各种异常。通过这种方式，可以保证异常信息不会丢失，并且可以在合适的时机将异常传递给调用者，从而实现异常的正确处理和传播。
